Exception on /api/bugs_info [GET]
Traceback (most recent call last):
  File "C:\Python27\lib\site-packages\flask\app.py", line 1817, in wsgi_app
    response = self.full_dispatch_request()
  File "C:\Python27\lib\site-packages\flask\app.py", line 1477, in full_dispatch_request
    rv = self.handle_user_exception(e)
  File "C:\Python27\lib\site-packages\flask\app.py", line 1381, in handle_user_exception
    reraise(exc_type, exc_value, tb)
  File "C:\Python27\lib\site-packages\flask\app.py", line 1475, in full_dispatch_request
    rv = self.dispatch_request()
  File "C:\Python27\lib\site-packages\flask\app.py", line 1461, in dispatch_request
    return self.view_functions[rule.endpoint](**req.view_args)
  File "web_ui.py", line 38, in get_handler
    raise ValueError("this is new bug")
ValueError: this is new bug
Exception on /api/bugs_info [GET]
Traceback (most recent call last):
  File "C:\Python27\lib\site-packages\flask\app.py", line 1817, in wsgi_app
    response = self.full_dispatch_request()
  File "C:\Python27\lib\site-packages\flask\app.py", line 1477, in full_dispatch_request
    rv = self.handle_user_exception(e)
  File "C:\Python27\lib\site-packages\flask\app.py", line 1381, in handle_user_exception
    reraise(exc_type, exc_value, tb)
  File "C:\Python27\lib\site-packages\flask\app.py", line 1475, in full_dispatch_request
    rv = self.dispatch_request()
  File "C:\Python27\lib\site-packages\flask\app.py", line 1461, in dispatch_request
    return self.view_functions[rule.endpoint](**req.view_args)
  File "web_ui.py", line 38, in get_handler
    raise ValueError("this is new bug")
ValueError: this is new bug
Exception on /api/bugs_info [GET]
Traceback (most recent call last):
  File "C:\Python27\lib\site-packages\flask\app.py", line 1817, in wsgi_app
    response = self.full_dispatch_request()
  File "C:\Python27\lib\site-packages\flask\app.py", line 1477, in full_dispatch_request
    rv = self.handle_user_exception(e)
  File "C:\Python27\lib\site-packages\flask\app.py", line 1381, in handle_user_exception
    reraise(exc_type, exc_value, tb)
  File "C:\Python27\lib\site-packages\flask\app.py", line 1475, in full_dispatch_request
    rv = self.dispatch_request()
  File "C:\Python27\lib\site-packages\flask\app.py", line 1461, in dispatch_request
    return self.view_functions[rule.endpoint](**req.view_args)
  File "web_ui.py", line 38, in get_handler
    raise ValueError("this is new bug")
ValueError: this is new bug
Exception on /api/bugs_info [GET]
Traceback (most recent call last):
  File "C:\Python27\lib\site-packages\flask\app.py", line 1817, in wsgi_app
    response = self.full_dispatch_request()
  File "C:\Python27\lib\site-packages\flask\app.py", line 1477, in full_dispatch_request
    rv = self.handle_user_exception(e)
  File "C:\Python27\lib\site-packages\flask\app.py", line 1381, in handle_user_exception
    reraise(exc_type, exc_value, tb)
  File "C:\Python27\lib\site-packages\flask\app.py", line 1475, in full_dispatch_request
    rv = self.dispatch_request()
  File "C:\Python27\lib\site-packages\flask\app.py", line 1461, in dispatch_request
    return self.view_functions[rule.endpoint](**req.view_args)
  File "web_ui.py", line 38, in get_handler
    raise ValueError("this is new bug")
ValueError: this is new bug
Exception on /api/bugs_info [GET]
Traceback (most recent call last):
  File "C:\Python27\lib\site-packages\flask\app.py", line 1817, in wsgi_app
    response = self.full_dispatch_request()
  File "C:\Python27\lib\site-packages\flask\app.py", line 1477, in full_dispatch_request
    rv = self.handle_user_exception(e)
  File "C:\Python27\lib\site-packages\flask\app.py", line 1381, in handle_user_exception
    reraise(exc_type, exc_value, tb)
  File "C:\Python27\lib\site-packages\flask\app.py", line 1475, in full_dispatch_request
    rv = self.dispatch_request()
  File "C:\Python27\lib\site-packages\flask\app.py", line 1461, in dispatch_request
    return self.view_functions[rule.endpoint](**req.view_args)
  File "web_ui.py", line 38, in get_handler
    raise ValueError("this is new bug")
ValueError: this is new bug
Exception on /api/bugs_info [GET]
Traceback (most recent call last):
  File "C:\Python27\lib\site-packages\flask\app.py", line 1817, in wsgi_app
    response = self.full_dispatch_request()
  File "C:\Python27\lib\site-packages\flask\app.py", line 1477, in full_dispatch_request
    rv = self.handle_user_exception(e)
  File "C:\Python27\lib\site-packages\flask\app.py", line 1381, in handle_user_exception
    reraise(exc_type, exc_value, tb)
  File "C:\Python27\lib\site-packages\flask\app.py", line 1475, in full_dispatch_request
    rv = self.dispatch_request()
  File "C:\Python27\lib\site-packages\flask\app.py", line 1461, in dispatch_request
    return self.view_functions[rule.endpoint](**req.view_args)
  File "web_ui.py", line 38, in get_handler
    raise ValueError("this is new bug")
ValueError: this is new bug
Exception on /api/bugs_info [GET]
Traceback (most recent call last):
  File "C:\Python27\lib\site-packages\flask\app.py", line 1817, in wsgi_app
    response = self.full_dispatch_request()
  File "C:\Python27\lib\site-packages\flask\app.py", line 1477, in full_dispatch_request
    rv = self.handle_user_exception(e)
  File "C:\Python27\lib\site-packages\flask\app.py", line 1381, in handle_user_exception
    reraise(exc_type, exc_value, tb)
  File "C:\Python27\lib\site-packages\flask\app.py", line 1475, in full_dispatch_request
    rv = self.dispatch_request()
  File "C:\Python27\lib\site-packages\flask\app.py", line 1461, in dispatch_request
    return self.view_functions[rule.endpoint](**req.view_args)
  File "web_ui.py", line 38, in get_handler
    raise ValueError("this is new bug")
ValueError: this is new bug
Exception on /api/bugs_info [GET]
Traceback (most recent call last):
  File "C:\Python27\lib\site-packages\flask\app.py", line 1817, in wsgi_app
    response = self.full_dispatch_request()
  File "C:\Python27\lib\site-packages\flask\app.py", line 1477, in full_dispatch_request
    rv = self.handle_user_exception(e)
  File "C:\Python27\lib\site-packages\flask\app.py", line 1381, in handle_user_exception
    reraise(exc_type, exc_value, tb)
  File "C:\Python27\lib\site-packages\flask\app.py", line 1475, in full_dispatch_request
    rv = self.dispatch_request()
  File "C:\Python27\lib\site-packages\flask\app.py", line 1461, in dispatch_request
    return self.view_functions[rule.endpoint](**req.view_args)
  File "web_ui.py", line 38, in get_handler
    # raise ValueError("this is new bug")
ValueError: this is new bug
Exception on /api/bugs_info [GET]
Traceback (most recent call last):
  File "C:\Python27\lib\site-packages\flask\app.py", line 1817, in wsgi_app
    response = self.full_dispatch_request()
  File "C:\Python27\lib\site-packages\flask\app.py", line 1477, in full_dispatch_request
    rv = self.handle_user_exception(e)
  File "C:\Python27\lib\site-packages\flask\app.py", line 1381, in handle_user_exception
    reraise(exc_type, exc_value, tb)
  File "C:\Python27\lib\site-packages\flask\app.py", line 1475, in full_dispatch_request
    rv = self.dispatch_request()
  File "C:\Python27\lib\site-packages\flask\app.py", line 1461, in dispatch_request
    return self.view_functions[rule.endpoint](**req.view_args)
  File "web_ui.py", line 38, in get_handler
    # raise ValueError("this is new bug")
ValueError: this is new bug
Exception on /api/bugs_info [GET]
Traceback (most recent call last):
  File "C:\Python27\lib\site-packages\flask\app.py", line 1817, in wsgi_app
    response = self.full_dispatch_request()
  File "C:\Python27\lib\site-packages\flask\app.py", line 1477, in full_dispatch_request
    rv = self.handle_user_exception(e)
  File "C:\Python27\lib\site-packages\flask\app.py", line 1381, in handle_user_exception
    reraise(exc_type, exc_value, tb)
  File "C:\Python27\lib\site-packages\flask\app.py", line 1475, in full_dispatch_request
    rv = self.dispatch_request()
  File "C:\Python27\lib\site-packages\flask\app.py", line 1461, in dispatch_request
    return self.view_functions[rule.endpoint](**req.view_args)
  File "web_ui.py", line 38, in get_handler
    # raise ValueError("this is new bug")
ValueError: this is new bug
Exception on /api/bugs_info [GET]
Traceback (most recent call last):
  File "C:\Python27\lib\site-packages\flask\app.py", line 1817, in wsgi_app
    response = self.full_dispatch_request()
  File "C:\Python27\lib\site-packages\flask\app.py", line 1477, in full_dispatch_request
    rv = self.handle_user_exception(e)
  File "C:\Python27\lib\site-packages\flask\app.py", line 1381, in handle_user_exception
    reraise(exc_type, exc_value, tb)
  File "C:\Python27\lib\site-packages\flask\app.py", line 1475, in full_dispatch_request
    rv = self.dispatch_request()
  File "C:\Python27\lib\site-packages\flask\app.py", line 1461, in dispatch_request
    return self.view_functions[rule.endpoint](**req.view_args)
  File "web_ui.py", line 38, in get_handler
    # raise ValueError("this is new bug")
ValueError: this is new bug
Exception on /api/bugs_info [GET]
Traceback (most recent call last):
  File "C:\Python27\lib\site-packages\flask\app.py", line 1817, in wsgi_app
    response = self.full_dispatch_request()
  File "C:\Python27\lib\site-packages\flask\app.py", line 1477, in full_dispatch_request
    rv = self.handle_user_exception(e)
  File "C:\Python27\lib\site-packages\flask\app.py", line 1381, in handle_user_exception
    reraise(exc_type, exc_value, tb)
  File "C:\Python27\lib\site-packages\flask\app.py", line 1475, in full_dispatch_request
    rv = self.dispatch_request()
  File "C:\Python27\lib\site-packages\flask\app.py", line 1461, in dispatch_request
    return self.view_functions[rule.endpoint](**req.view_args)
  File "web_ui.py", line 38, in get_handler
    # raise ValueError("this is new bug")
ValueError: this is new bug
local variable 'e' referenced before assignment
local variable 'e' referenced before assignment
local variable 'e' referenced before assignment
research_coding_line
Exception on /api/special_test_receipt [POST]
Traceback (most recent call last):
  File "C:\Python26\lib\site-packages\flask-0.10.1-py2.6.egg\flask\app.py", line 1817, in wsgi_app
    response = self.full_dispatch_request()
  File "C:\Python26\lib\site-packages\flask-0.10.1-py2.6.egg\flask\app.py", line 1477, in full_dispatch_request
    rv = self.handle_user_exception(e)
  File "C:\Python26\lib\site-packages\flask-0.10.1-py2.6.egg\flask\app.py", line 1381, in handle_user_exception
    reraise(exc_type, exc_value, tb)
  File "C:\Python26\lib\site-packages\flask-0.10.1-py2.6.egg\flask\app.py", line 1475, in full_dispatch_request
    rv = self.dispatch_request()
  File "C:\Python26\lib\site-packages\flask-0.10.1-py2.6.egg\flask\app.py", line 1461, in dispatch_request
    return self.view_functions[rule.endpoint](**req.view_args)
  File "web_ui.py", line 134, in api_create_special_test_receipt_handler
    raise e
AttributeError: research_coding_line
creator
creator
creator
creator
parents_id
parents_id
parents_id
author
(1366, "Incorrect integer value: '\xe5\x90\xa6' for column 'is_solved' at row 1")
cannot concatenate 'str' and 'list' objects
cannot concatenate 'str' and 'list' objects
cannot concatenate 'str' and 'list' objects
cannot concatenate 'str' and 'list' objects
cannot concatenate 'str' and 'list' objects
Exception on /api/bugs_info [GET]
Traceback (most recent call last):
  File "C:\Python26\lib\site-packages\flask-0.10.1-py2.6.egg\flask\app.py", line 1817, in wsgi_app
    response = self.full_dispatch_request()
  File "C:\Python26\lib\site-packages\flask-0.10.1-py2.6.egg\flask\app.py", line 1477, in full_dispatch_request
    rv = self.handle_user_exception(e)
  File "C:\Python26\lib\site-packages\flask-0.10.1-py2.6.egg\flask\app.py", line 1381, in handle_user_exception
    reraise(exc_type, exc_value, tb)
  File "C:\Python26\lib\site-packages\flask-0.10.1-py2.6.egg\flask\app.py", line 1475, in full_dispatch_request
    rv = self.dispatch_request()
  File "C:\Python26\lib\site-packages\flask-0.10.1-py2.6.egg\flask\app.py", line 1461, in dispatch_request
    return self.view_functions[rule.endpoint](**req.view_args)
  File "web_ui.py", line 74, in get_handler
    raise e
TypeError: cannot concatenate 'str' and 'list' objects
cannot concatenate 'str' and 'list' objects
Exception on /api/bugs_info [GET]
Traceback (most recent call last):
  File "C:\Python26\lib\site-packages\flask-0.10.1-py2.6.egg\flask\app.py", line 1817, in wsgi_app
    response = self.full_dispatch_request()
  File "C:\Python26\lib\site-packages\flask-0.10.1-py2.6.egg\flask\app.py", line 1477, in full_dispatch_request
    rv = self.handle_user_exception(e)
  File "C:\Python26\lib\site-packages\flask-0.10.1-py2.6.egg\flask\app.py", line 1381, in handle_user_exception
    reraise(exc_type, exc_value, tb)
  File "C:\Python26\lib\site-packages\flask-0.10.1-py2.6.egg\flask\app.py", line 1475, in full_dispatch_request
    rv = self.dispatch_request()
  File "C:\Python26\lib\site-packages\flask-0.10.1-py2.6.egg\flask\app.py", line 1461, in dispatch_request
    return self.view_functions[rule.endpoint](**req.view_args)
  File "web_ui.py", line 74, in get_handler
    raise e
TypeError: cannot concatenate 'str' and 'list' objects
cannot concatenate 'str' and 'list' objects
Exception on /api/bugs_info [GET]
Traceback (most recent call last):
  File "C:\Python26\lib\site-packages\flask-0.10.1-py2.6.egg\flask\app.py", line 1817, in wsgi_app
    response = self.full_dispatch_request()
  File "C:\Python26\lib\site-packages\flask-0.10.1-py2.6.egg\flask\app.py", line 1477, in full_dispatch_request
    rv = self.handle_user_exception(e)
  File "C:\Python26\lib\site-packages\flask-0.10.1-py2.6.egg\flask\app.py", line 1381, in handle_user_exception
    reraise(exc_type, exc_value, tb)
  File "C:\Python26\lib\site-packages\flask-0.10.1-py2.6.egg\flask\app.py", line 1475, in full_dispatch_request
    rv = self.dispatch_request()
  File "C:\Python26\lib\site-packages\flask-0.10.1-py2.6.egg\flask\app.py", line 1461, in dispatch_request
    return self.view_functions[rule.endpoint](**req.view_args)
  File "web_ui.py", line 74, in get_handler
    raise e
TypeError: cannot concatenate 'str' and 'list' objects
